Workbook

Sheet Full-Sample Sweep
A1: Gold-Stock ETF Factor Regression — Full-Sample Sweep (computed live via LINEST on the Daily Data / Regression Inputs sheets)
A2: ER(vehicle) = alpha + betas*ER(factors), factors from {SPY, IAU, GLD, TLT}. Alpha shown in bps/day (Alpha*10000). p-values via two-tailed t-test, df = N-k-1.
A4: Vehicle | B4: Factors | C4: NumFactors | D4: N | E4: Alpha_bps | F4: Alpha_t | G4: Alpha_p | H4: Beta_SPY | I4: t_SPY | J4: p_SPY | K4: Beta_IAU | L4: t_IAU | M4: p_IAU | N4: Beta_GLD | O4: t_GLD | P4: p_GLD | Q4: Beta_TLT | R4: t_TLT | S4: p_TLT | T4: R2 | U4: AdjR2 | V4: AIC | W4: BIC
A5: GDX | B5: SPY+IAU+GLD+TLT | C5: 4 | D5: =COUNT('Daily Data'!S$4:S$3934) -> 3931 | E5: =INDEX(LINEST('Daily Data'!S$4:S$3934,'Regression Inputs'!$AQ$5:$AT$3935,TRUE(),TRUE()),1,5)*10000 -> -4.2621171 | F5: =INDEX(LINEST('Daily Data'!S$4:S$3934,'Regression Inputs'!$AQ$5:$AT$3935,TRUE(),TRUE()),1,5)/INDEX(LINEST('Daily Data'!S$4:S$3934,'Regression Inputs'!$AQ$5:$AT$3935,TRUE(),TRUE()),2,5) -> -1.6620999 | G5: =TDIST(ABS(F5),INDEX(LINEST('Daily Data'!S$4:S$3934,'Regression Inputs'!$AQ$5:$AT$3935,TRUE(),TRUE()),4,2),2) -> 0.096572576 | H5: =INDEX(LINEST('Daily Data'!S$4:S$3934,'Regression Inputs'!$AQ$5:$AT$3935,TRUE(),TRUE()),1,4) -> 0.52480052 | I5: =H5/INDEX(LINEST('Daily Data'!S$4:S$3934,'Regression Inputs'!$AQ$5:$AT$3935,TRUE(),TRUE()),2,4) -> 22.899632 | J5: =TDIST(ABS(I5),INDEX(LINEST('Daily Data'!S$4:S$3934,'Regression Inputs'!$AQ$5:$AT$3935,TRUE(),TRUE()),4,2),2) -> 4.8629191e-109 | K5: =INDEX(LINEST('Daily Data'!S$4:S$3934,'Regression Inputs'!$AQ$5:$AT$3935,TRUE(),TRUE()),1,3) -> 0.26563941 | L5: =K5/INDEX(LINEST('Daily Data'!S$4:S$3934,'Regression Inputs'!$AQ$5:$AT$3935,TRUE(),TRUE()),2,3) -> 1.0217575 | M5: =TDIST(ABS(L5),INDEX(LINEST('Daily Data'!S$4:S$3934,'Regression Inputs'!$AQ$5:$AT$3935,TRUE(),TRUE()),4,2),2) -> 0.30695863 | N5: =INDEX(LINEST('Daily Data'!S$4:S$3934,'Regression Inputs'!$AQ$5:$AT$3935,TRUE(),TRUE()),1,2) -> 1.4670723 | O5: =N5/INDEX(LINEST('Daily Data'!S$4:S$3934,'Regression Inputs'!$AQ$5:$AT$3935,TRUE(),TRUE()),2,2) -> 5.6126881 | P5: =TDIST(ABS(O5),INDEX(LINEST('Daily Data'!S$4:S$3934,'Regression Inputs'!$AQ$5:$AT$3935,TRUE(),TRUE()),4,2),2) -> 2.1296964e-08 | Q5: =INDEX(LINEST('Daily Data'!S$4:S$3934,'Regression Inputs'!$AQ$5:$AT$3935,TRUE(),TRUE()),1,1) -> 0.085486084 | R5: =Q5/INDEX(LINEST('Daily Data'!S$4:S$3934,'Regression Inputs'!$AQ$5:$AT$3935,TRUE(),TRUE()),2,1) -> 2.7127998 | S5: =TDIST(ABS(R5),INDEX(LINEST('Daily Data'!S$4:S$3934,'Regression Inputs'!$AQ$5:$AT$3935,TRUE(),TRUE()),4,2),2) -> 0.0067008413 | T5: =INDEX(LINEST('Daily Data'!S$4:S$3934,'Regression Inputs'!$AQ$5:$AT$3935,TRUE(),TRUE()),3,1) -> 0.63161011 | U5: =1-(1-T5)*(D5-1)/(D5-4-1) -> 0.63123478 | V5: =D5*LN(2*PI())+D5*LN(INDEX(LINEST('Daily Data'!S$4:S$3934,'Regression Inputs'!$AQ$5:$AT$3935,TRUE(),TRUE()),5,2)/D5)+D5+2*(4+1) -> -21327.281 | W5: =D5*LN(2*PI())+D5*LN(INDEX(LINEST('Daily Data'!S$4:S$3934,'Regression Inputs'!$AQ$5:$AT$3935,TRUE(),TRUE()),5,2)/D5)+D5+LN(D5)*(4+1) -> -21295.898
A6: GDX | B6: SPY+GLD+TLT | C6: 3 | D6: =COUNT('Daily Data'!S$4:S$3934) -> 3931 | E6: =INDEX(LINEST('Daily Data'!S$4:S$3934,'Regression Inputs'!$AI$5:$AK$3935,TRUE(),TRUE()),1,4)*10000 -> -4.2478357 | F6: =INDEX(LINEST('Daily Data'!S$4:S$3934,'Regression Inputs'!$AI$5:$AK$3935,TRUE(),TRUE()),1,4)/INDEX(LINEST('Daily Data'!S$4:S$3934,'Regression Inputs'!$AI$5:$AK$3935,TRUE(),TRUE()),2,4) -> -1.6565459 | G6: =TDIST(ABS(F6),INDEX(LINEST('Daily Data'!S$4:S$3934,'Regression Inputs'!$AI$5:$AK$3935,TRUE(),TRUE()),4,2),2) -> 0.097691206 | H6: =INDEX(LINEST('Daily Data'!S$4:S$3934,'Regression Inputs'!$AI$5:$AK$3935,TRUE(),TRUE()),1,3) -> 0.52481045 | I6: =H6/INDEX(LINEST('Daily Data'!S$4:S$3934,'Regression Inputs'!$AI$5:$AK$3935,TRUE(),TRUE()),2,3) -> 22.899939 | J6: =TDIST(ABS(I6),INDEX(LINEST('Daily Data'!S$4:S$3934,'Regression Inputs'!$AI$5:$AK$3935,TRUE(),TRUE()),4,2),2) -> 4.8145259e-109 | N6: =INDEX(LINEST('Daily Data'!S$4:S$3934,'Regression Inputs'!$AI$5:$AK$3935,TRUE(),TRUE()),1,2) -> 1.7331108 | O6: =N6/INDEX(LINEST('Daily Data'!S$4:S$3934,'Regression Inputs'!$AI$5:$AK$3935,TRUE(),TRUE()),2,2) -> 75.438947 | P6: =TDIST(ABS(O6),INDEX(LINEST('Daily Data'!S$4:S$3934,'Regression Inputs'!$AI$5:$AK$3935,TRUE(),TRUE()),4,2),2) -> 0 | Q6: =INDEX(LINEST('Daily Data'!S$4:S$3934,'Regression Inputs'!$AI$5:$AK$3935,TRUE(),TRUE()),1,1) -> 0.0845915 | R6: =Q6/INDEX(LINEST('Daily Data'!S$4:S$3934,'Regression Inputs'!$AI$5:$AK$3935,TRUE(),TRUE()),2,1) -> 2.6854329 | S6: =TDIST(ABS(R6),INDEX(LINEST('Daily Data'!S$4:S$3934,'Regression Inputs'!$AI$5:$AK$3935,TRUE(),TRUE()),4,2),2) -> 0.0072740499 | T6: =INDEX(LINEST('Daily Data'!S$4:S$3934,'Regression Inputs'!$AI$5:$AK$3935,TRUE(),TRUE()),3,1) -> 0.63151215 | U6: =1-(1-T6)*(D6-1)/(D6-3-1) -> 0.63123064 | V6: =D6*LN(2*PI())+D6*LN(INDEX(LINEST('Daily Data'!S$4:S$3934,'Regression Inputs'!$AI$5:$AK$3935,TRUE(),TRUE()),5,2)/D6)+D6+2*(3+1) -> -21328.236 | W6: =D6*LN(2*PI())+D6*LN(INDEX(LINEST('Daily Data'!S$4:S$3934,'Regression Inputs'!$AI$5:$AK$3935,TRUE(),TRUE()),5,2)/D6)+D6+LN(D6)*(3+1) -> -21303.13
A7: GDX | B7: SPY+GLD | C7: 2 | D7: =COUNT('Daily Data'!S$4:S$3934) -> 3931 | E7: =INDEX(LINEST('Daily Data'!S$4:S$3934,'Regression Inputs'!$L$5:$M$3935,TRUE(),TRUE()),1,3)*10000 -> -3.9346891 | F7: =INDEX(LINEST('Daily Data'!S$4:S$3934,'Regression Inputs'!$L$5:$M$3935,TRUE(),TRUE()),1,3)/INDEX(LINEST('Daily Data'!S$4:S$3934,'Regression Inputs'!$L$5:$M$3935,TRUE(),TRUE()),2,3) -> -1.5348028 | G7: =TDIST(ABS(F7),INDEX(LINEST('Daily Data'!S$4:S$3934,'Regression Inputs'!$L$5:$M$3935,TRUE(),TRUE()),4,2),2) -> 0.12491281 | H7: =INDEX(LINEST('Daily Data'!S$4:S$3934,'Regression Inputs'!$L$5:$M$3935,TRUE(),TRUE()),1,2) -> 0.49793497 | I7: =H7/INDEX(LINEST('Daily Data'!S$4:S$3934,'Regression Inputs'!$L$5:$M$3935,TRUE(),TRUE()),2,2) -> 24.132719 | J7: =TDIST(ABS(I7),INDEX(LINEST('Daily Data'!S$4:S$3934,'Regression Inputs'!$L$5:$M$3935,TRUE(),TRUE()),4,2),2) -> 4.2193293e-120 | N7: =INDEX(LINEST('Daily Data'!S$4:S$3934,'Regression Inputs'!$L$5:$M$3935,TRUE(),TRUE()),1,1) -> 1.7443967 | O7: =N7/INDEX(LINEST('Daily Data'!S$4:S$3934,'Regression Inputs'!$L$5:$M$3935,TRUE(),TRUE()),2,1) -> 77.172489 | P7: =TDIST(ABS(O7),INDEX(LINEST('Daily Data'!S$4:S$3934,'Regression Inputs'!$L$5:$M$3935,TRUE(),TRUE()),4,2),2) -> 0 | T7: =INDEX(LINEST('Daily Data'!S$4:S$3934,'Regression Inputs'!$L$5:$M$3935,TRUE(),TRUE()),3,1) -> 0.63083546 | U7: =1-(1-T7)*(D7-1)/(D7-2-1) -> 0.63064749 | V7: =D7*LN(2*PI())+D7*LN(INDEX(LINEST('Daily Data'!S$4:S$3934,'Regression Inputs'!$L$5:$M$3935,TRUE(),TRUE()),5,2)/D7)+D7+2*(2+1) -> -21323.024 | W7: =D7*LN(2*PI())+D7*LN(INDEX(LINEST('Daily Data'!S$4:S$3934,'Regression Inputs'!$L$5:$M$3935,TRUE(),TRUE()),5,2)/D7)+D7+LN(D7)*(2+1) -> -21304.194
A8: GDX | B8: SPY+IAU+GLD | C8: 3 | D8: =COUNT('Daily Data'!S$4:S$3934) -> 3931 | E8: =INDEX(LINEST('Daily Data'!S$4:S$3934,'Regression Inputs'!$AA$5:$AC$3935,TRUE(),TRUE()),1,4)*10000 -> -3.9448497 | F8: =INDEX(LINEST('Daily Data'!S$4:S$3934,'Regression Inputs'!$AA$5:$AC$3935,TRUE(),TRUE()),1,4)/INDEX(LINEST('Daily Data'!S$4:S$3934,'Regression Inputs'!$AA$5:$AC$3935,TRUE(),TRUE()),2,4) -> -1.5387321 | G8: =TDIST(ABS(F8),INDEX(LINEST('Daily Data'!S$4:S$3934,'Regression Inputs'!$AA$5:$AC$3935,TRUE(),TRUE()),4,2),2) -> 0.12395029 | H8: =INDEX(LINEST('Daily Data'!S$4:S$3934,'Regression Inputs'!$AA$5:$AC$3935,TRUE(),TRUE()),1,3) -> 0.49766252 | I8: =H8/INDEX(LINEST('Daily Data'!S$4:S$3934,'Regression Inputs'!$AA$5:$AC$3935,TRUE(),TRUE()),2,3) -> 24.116842 | J8: =TDIST(ABS(I8),INDEX(LINEST('Daily Data'!S$4:S$3934,'Regression Inputs'!$AA$5:$AC$3935,TRUE(),TRUE()),4,2),2) -> 5.9204203e-120 | K8: =INDEX(LINEST('Daily Data'!S$4:S$3934,'Regression Inputs'!$AA$5:$AC$3935,TRUE(),TRUE()),1,2) -> 0.24604384 | L8: =K8/INDEX(LINEST('Daily Data'!S$4:S$3934,'Regression Inputs'!$AA$5:$AC$3935,TRUE(),TRUE()),2,2) -> 0.94598484 | M8: =TDIST(ABS(L8),INDEX(LINEST('Daily Data'!S$4:S$3934,'Regression Inputs'!$AA$5:$AC$3935,TRUE(),TRUE()),4,2),2) -> 0.34421452 | N8: =INDEX(LINEST('Daily Data'!S$4:S$3934,'Regression Inputs'!$AA$5:$AC$3935,TRUE(),TRUE()),1,1) -> 1.4980938 | O8: =N8/INDEX(LINEST('Daily Data'!S$4:S$3934,'Regression Inputs'!$AA$5:$AC$3935,TRUE(),TRUE()),2,1) -> 5.7322225 | P8: =TDIST(ABS(O8),INDEX(LINEST('Daily Data'!S$4:S$3934,'Regression Inputs'!$AA$5:$AC$3935,TRUE(),TRUE()),4,2),2) -> 1.0657308e-08 | T8: =INDEX(LINEST('Daily Data'!S$4:S$3934,'Regression Inputs'!$AA$5:$AC$3935,TRUE(),TRUE()),3,1) -> 0.63091956 | U8: =1-(1-T8)*(D8-1)/(D8-3-1) -> 0.63063761 | V8: =D8*LN(2*PI())+D8*LN(INDEX(LINEST('Daily Data'!S$4:S$3934,'Regression Inputs'!$AA$5:$AC$3935,TRUE(),TRUE()),5,2)/D8)+D8+2*(3+1) -> -21321.92 | W8: =D8*LN(2*PI())+D8*LN(INDEX(LINEST('Daily Data'!S$4:S$3934,'Regression Inputs'!$AA$5:$AC$3935,TRUE(),TRUE()),5,2)/D8)+D8+LN(D8)*(3+1) -> -21296.813
A9: GDX | B9: SPY+IAU+TLT | C9: 3 | D9: =COUNT('Daily Data'!S$4:S$3934) -> 3931 | E9: =INDEX(LINEST('Daily Data'!S$4:S$3934,'Regression Inputs'!$AE$5:$AG$3935,TRUE(),TRUE()),1,4)*10000 -> -4.3235527 | F9: =INDEX(LINEST('Daily Data'!S$4:S$3934,'Regression Inputs'!$AE$5:$AG$3935,TRUE(),TRUE()),1,4)/INDEX(LINEST('Daily Data'!S$4:S$3934,'Regression Inputs'!$AE$5:$AG$3935,TRUE(),TRUE()),2,4) -> -1.6795631 | G9: =TDIST(ABS(F9),INDEX(LINEST('Daily Data'!S$4:S$3934,'Regression Inputs'!$AE$5:$AG$3935,TRUE(),TRUE()),4,2),2) -> 0.0931219 | H9: =INDEX(LINEST('Daily Data'!S$4:S$3934,'Regression Inputs'!$AE$5:$AG$3935,TRUE(),TRUE()),1,3) -> 0.52608317 | I9: =H9/INDEX(LINEST('Daily Data'!S$4:S$3934,'Regression Inputs'!$AE$5:$AG$3935,TRUE(),TRUE()),2,3) -> 22.868102 | J9: =TDIST(ABS(I9),INDEX(LINEST('Daily Data'!S$4:S$3934,'Regression Inputs'!$AE$5:$AG$3935,TRUE(),TRUE()),4,2),2) -> 9.1678945e-109 | K9: =INDEX(LINEST('Daily Data'!S$4:S$3934,'Regression Inputs'!$AE$5:$AG$3935,TRUE(),TRUE()),1,2) -> 1.7191949 | L9: =K9/INDEX(LINEST('Daily Data'!S$4:S$3934,'Regression Inputs'!$AE$5:$AG$3935,TRUE(),TRUE()),2,2) -> 74.946722 | M9: =TDIST(ABS(L9),INDEX(LINEST('Daily Data'!S$4:S$3934,'Regression Inputs'!$AE$5:$AG$3935,TRUE(),TRUE()),4,2),2) -> 0 | Q9: =INDEX(LINEST('Daily Data'!S$4:S$3934,'Regression Inputs'!$AE$5:$AG$3935,TRUE(),TRUE()),1,1) -> 0.093223796 | R9: =Q9/INDEX(LINEST('Daily Data'!S$4:S$3934,'Regression Inputs'!$AE$5:$AG$3935,TRUE(),TRUE()),2,1) -> 2.9497483 | S9: =TDIST(ABS(R9),INDEX(LINEST('Daily Data'!S$4:S$3934,'Regression Inputs'!$AE$5:$AG$3935,TRUE(),TRUE()),4,2),2) -> 0.0031991081 | T9: =INDEX(LINEST('Daily Data'!S$4:S$3934,'Regression Inputs'!$AE$5:$AG$3935,TRUE(),TRUE()),3,1) -> 0.62865414 | U9: =1-(1-T9)*(D9-1)/(D9-3-1) -> 0.62837046 | V9: =D9*LN(2*PI())+D9*LN(INDEX(LINEST('Daily Data'!S$4:S$3934,'Regression Inputs'!$AE$5:$AG$3935,TRUE(),TRUE()),5,2)/D9)+D9+2*(3+1) -> -21297.865 | W9: =D9*LN(2*PI())+D9*LN(INDEX(LINEST('Daily Data'!S$4:S$3934,'Regression Inputs'!$AE$5:$AG$3935,TRUE(),TRUE()),5,2)/D9)+D9+LN(D9)*(3+1) -> -21272.758
A10: GDX | B10: SPY+IAU | C10: 2 | D10: =COUNT('Daily Data'!S$4:S$3934) -> 3931 | E10: =INDEX(LINEST('Daily Data'!S$4:S$3934,'Regression Inputs'!$I$5:$J$3935,TRUE(),TRUE()),1,3)*10000 -> -3.9783239 | F10: =INDEX(LINEST('Daily Data'!S$4:S$3934,'Regression Inputs'!$I$5:$J$3935,TRUE(),TRUE()),1,3)/INDEX(LINEST('Daily Data'!S$4:S$3934,'Regression Inputs'!$I$5:$J$3935,TRUE(),TRUE()),2,3) -> -1.5455381 | G10: =TDIST(ABS(F10),INDEX(LINEST('Daily Data'!S$4:S$3934,'Regression Inputs'!$I$5:$J$3935,TRUE(),TRUE()),4,2),2) -> 0.12229671 | H10: =INDEX(LINEST('Daily Data'!S$4:S$3934,'Regression Inputs'!$I$5:$J$3935,TRUE(),TRUE()),1,2) -> 0.49646167 | I10: =H10/INDEX(LINEST('Daily Data'!S$4:S$3934,'Regression Inputs'!$I$5:$J$3935,TRUE(),TRUE()),2,2) -> 23.962908 | J10: =TDIST(ABS(I10),INDEX(LINEST('Daily Data'!S$4:S$3934,'Regression Inputs'!$I$5:$J$3935,TRUE(),TRUE()),4,2),2) -> 1.4920467e-118 | K10: =INDEX(LINEST('Daily Data'!S$4:S$3934,'Regression Inputs'!$I$5:$J$3935,TRUE(),TRUE()),1,1) -> 1.7313666 | L10: =K10/INDEX(LINEST('Daily Data'!S$4:S$3934,'Regression Inputs'!$I$5:$J$3935,TRUE(),TRUE()),2,1) -> 76.653858 | M10: =TDIST(ABS(L10),INDEX(LINEST('Daily Data'!S$4:S$3934,'Regression Inputs'!$I$5:$J$3935,TRUE(),TRUE()),4,2),2) -> 0 | T10: =INDEX(LINEST('Daily Data'!S$4:S$3934,'Regression Inputs'!$I$5:$J$3935,TRUE(),TRUE()),3,1) -> 0.62783136 | U10: =1-(1-T10)*(D10-1)/(D10-2-1) -> 0.62764186 | V10: =D10*LN(2*PI())+D10*LN(INDEX(LINEST('Daily Data'!S$4:S$3934,'Regression Inputs'!$I$5:$J$3935,TRUE(),TRUE()),5,2)/D10)+D10+2*(2+1) -> -21291.165 | W10: =D10*LN(2*PI())+D10*LN(INDEX(LINEST('Daily Data'!S$4:S$3934,'Regression Inputs'!$I$5:$J$3935,TRUE(),TRUE()),5,2)/D10)+D10+LN(D10)*(2+1) -> -21272.335
A11: GDX | B11: GLD+TLT | C11: 2 | D11: =COUNT('Daily Data'!S$4:S$3934) -> 3931 | E11: =INDEX(LINEST('Daily Data'!S$4:S$3934,'Regression Inputs'!$X$5:$Y$3935,TRUE(),TRUE()),1,3)*10000 -> -1.2224612 | F11: =INDEX(LINEST('Daily Data'!S$4:S$3934,'Regression Inputs'!$X$5:$Y$3935,TRUE(),TRUE()),1,3)/INDEX(LINEST('Daily Data'!S$4:S$3934,'Regression Inputs'!$X$5:$Y$3935,TRUE(),TRUE()),2,3) -> -0.44842012 | G11: =TDIST(ABS(F11),INDEX(LINEST('Daily Data'!S$4:S$3934,'Regression Inputs'!$X$5:$Y$3935,TRUE(),TRUE()),4,2),2) -> 0.65387476 | N11: =INDEX(LINEST('Daily Data'!S$4:S$3934,'Regression Inputs'!$X$5:$Y$3935,TRUE(),TRUE()),1,2) -> 1.7953278 | O11: =N11/INDEX(LINEST('Daily Data'!S$4:S$3934,'Regression Inputs'!$X$5:$Y$3935,TRUE(),TRUE()),2,2) -> 73.927931 | P11: =TDIST(ABS(O11),INDEX(LINEST('Daily Data'!S$4:S$3934,'Regression Inputs'!$X$5:$Y$3935,TRUE(),TRUE()),4,2),2) -> 0 | Q11: =INDEX(LINEST('Daily Data'!S$4:S$3934,'Regression Inputs'!$X$5:$Y$3935,TRUE(),TRUE()),1,1) -> -0.23041583 | R11: =Q11/INDEX(LINEST('Daily Data'!S$4:S$3934,'Regression Inputs'!$X$5:$Y$3935,TRUE(),TRUE()),2,1) -> -7.6380385 | S11: =TDIST(ABS(R11),INDEX(LINEST('Daily Data'!S$4:S$3934,'Regression Inputs'!$X$5:$Y$3935,TRUE(),TRUE()),4,2),2) -> 2.7532834e-14 | T11: =INDEX(LINEST('Daily Data'!S$4:S$3934,'Regression Inputs'!$X$5:$Y$3935,TRUE(),TRUE()),3,1) -> 0.58230469 | U11: =1-(1-T11)*(D11-1)/(D11-2-1) -> 0.58209201 | V11: =D11*LN(2*PI())+D11*LN(INDEX(LINEST('Daily Data'!S$4:S$3934,'Regression Inputs'!$X$5:$Y$3935,TRUE(),TRUE()),5,2)/D11)+D11+2*(2+1) -> -20837.507 | W11: =D11*LN(2*PI())+D11*LN(INDEX(LINEST('Daily Data'!S$4:S$3934,'Regression Inputs'!$X$5:$Y$3935,TRUE(),TRUE()),5,2)/D11)+D11+LN(D11)*(2+1) -> -20818.677
A12: GDX | B12: IAU+GLD+TLT | C12: 3 | D12: =COUNT('Daily Data'!S$4:S$3934) -> 3931 | E12: =INDEX(LINEST('Daily Data'!S$4:S$3934,'Regression Inputs'!$AM$5:$AO$3935,TRUE(),TRUE()),1,4)*10000 -> -1.2369362 | F12: =INDEX(LINEST('Daily Data'!S$4:S$3934,'Regression Inputs'!$AM$5:$AO$3935,TRUE(),TRUE()),1,4)/INDEX(LINEST('Daily Data'!S$4:S$3934,'Regression Inputs'!$AM$5:$AO$3935,TRUE(),TRUE()),2,4) -> -0.45371945 | G12: =TDIST(ABS(F12),INDEX(LINEST('Daily Data'!S$4:S$3934,'Regression Inputs'!$AM$5:$AO$3935,TRUE(),TRUE()),4,2),2) -> 0.65005584 | K12: =INDEX(LINEST('Daily Data'!S$4:S$3934,'Regression Inputs'!$AM$5:$AO$3935,TRUE(),TRUE()),1,3) -> 0.26816443 | L12: =K12/INDEX(LINEST('Daily Data'!S$4:S$3934,'Regression Inputs'!$AM$5:$AO$3935,TRUE(),TRUE()),2,3) -> 0.96891976 | M12: =TDIST(ABS(L12),INDEX(LINEST('Daily Data'!S$4:S$3934,'Regression Inputs'!$AM$5:$AO$3935,TRUE(),TRUE()),4,2),2) -> 0.3326449 | N12: =INDEX(LINEST('Daily Data'!S$4:S$3934,'Regression Inputs'!$AM$5:$AO$3935,TRUE(),TRUE()),1,2) -> 1.5267593 | O12: =N12/INDEX(LINEST('Daily Data'!S$4:S$3934,'Regression Inputs'!$AM$5:$AO$3935,TRUE(),TRUE()),2,2) -> 5.4870994 | P12: =TDIST(ABS(O12),INDEX(LINEST('Daily Data'!S$4:S$3934,'Regression Inputs'!$AM$5:$AO$3935,TRUE(),TRUE()),4,2),2) -> 4.3436732e-08 | Q12: =INDEX(LINEST('Daily Data'!S$4:S$3934,'Regression Inputs'!$AM$5:$AO$3935,TRUE(),TRUE()),1,1) -> -0.22950672 | R12: =Q12/INDEX(LINEST('Daily Data'!S$4:S$3934,'Regression Inputs'!$AM$5:$AO$3935,TRUE(),TRUE()),2,1) -> -7.6041663 | S12: =TDIST(ABS(R12),INDEX(LINEST('Daily Data'!S$4:S$3934,'Regression Inputs'!$AM$5:$AO$3935,TRUE(),TRUE()),4,2),2) -> 3.5660893e-14 | T12: =INDEX(LINEST('Daily Data'!S$4:S$3934,'Regression Inputs'!$AM$5:$AO$3935,TRUE(),TRUE()),3,1) -> 0.58240452 | U12: =1-(1-T12)*(D12-1)/(D12-3-1) -> 0.5820855 | V12: =D12*LN(2*PI())+D12*LN(INDEX(LINEST('Daily Data'!S$4:S$3934,'Regression Inputs'!$AM$5:$AO$3935,TRUE(),TRUE()),5,2)/D12)+D12+2*(3+1) -> -20836.447 | W12: =D12*LN(2*PI())+D12*LN(INDEX(LINEST('Daily Data'!S$4:S$3934,'Regression Inputs'!$AM$5:$AO$3935,TRUE(),TRUE()),5,2)/D12)+D12+LN(D12)*(3+1) -> -20811.34
A13: GDX | B13: IAU+TLT | C13: 2 | D13: =COUNT('Daily Data'!S$4:S$3934) -> 3931 | E13: =INDEX(LINEST('Daily Data'!S$4:S$3934,'Regression Inputs'!$U$5:$V$3935,TRUE(),TRUE()),1,3)*10000 -> -1.2931823 | F13: =INDEX(LINEST('Daily Data'!S$4:S$3934,'Regression Inputs'!$U$5:$V$3935,TRUE(),TRUE()),1,3)/INDEX(LINEST('Daily Data'!S$4:S$3934,'Regression Inputs'!$U$5:$V$3935,TRUE(),TRUE()),2,3) -> -0.47260649 | G13: =TDIST(ABS(F13),INDEX(LINEST('Daily Data'!S$4:S$3934,'Regression Inputs'!$U$5:$V$3935,TRUE(),TRUE()),4,2),2) -> 0.63652021 | K13: =INDEX(LINEST('Daily Data'!S$4:S$3934,'Regression Inputs'!$U$5:$V$3935,TRUE(),TRUE()),1,2) -> 1.7810138 | L13: =K13/INDEX(LINEST('Daily Data'!S$4:S$3934,'Regression Inputs'!$U$5:$V$3935,TRUE(),TRUE()),2,2) -> 73.45813 | M13: =TDIST(ABS(L13),INDEX(LINEST('Daily Data'!S$4:S$3934,'Regression Inputs'!$U$5:$V$3935,TRUE(),TRUE()),4,2),2) -> 0 | Q13: =INDEX(LINEST('Daily Data'!S$4:S$3934,'Regression Inputs'!$U$5:$V$3935,TRUE(),TRUE()),1,1) -> -0.22225467 | R13: =Q13/INDEX(LINEST('Daily Data'!S$4:S$3934,'Regression Inputs'!$U$5:$V$3935,TRUE(),TRUE()),2,1) -> -7.3437969 | S13: =TDIST(ABS(R13),INDEX(LINEST('Daily Data'!S$4:S$3934,'Regression Inputs'!$U$5:$V$3935,TRUE(),TRUE()),4,2),2) -> 2.5111355e-13 | T13: =INDEX(LINEST('Daily Data'!S$4:S$3934,'Regression Inputs'!$U$5:$V$3935,TRUE(),TRUE()),3,1) -> 0.57920282 | U13: =1-(1-T13)*(D13-1)/(D13-2-1) -> 0.57898857 | V13: =D13*LN(2*PI())+D13*LN(INDEX(LINEST('Daily Data'!S$4:S$3934,'Regression Inputs'!$U$5:$V$3935,TRUE(),TRUE()),5,2)/D13)+D13+2*(2+1) -> -20808.423 | W13: =D13*LN(2*PI())+D13*LN(INDEX(LINEST('Daily Data'!S$4:S$3934,'Regression Inputs'!$U$5:$V$3935,TRUE(),TRUE()),5,2)/D13)+D13+LN(D13)*(2+1) -> -20789.593
A14: GDX | B14: IAU+GLD | C14: 2 | D14: =COUNT('Daily Data'!S$4:S$3934) -> 3931 | E14: =INDEX(LINEST('Daily Data'!S$4:S$3934,'Regression Inputs'!$R$5:$S$3935,TRUE(),TRUE()),1,3)*10000 -> -1.7703666 | F14: =INDEX(LINEST('Daily Data'!S$4:S$3934,'Regression Inputs'!$R$5:$S$3935,TRUE(),TRUE()),1,3)/INDEX(LINEST('Daily Data'!S$4:S$3934,'Regression Inputs'!$R$5:$S$3935,TRUE(),TRUE()),2,3) -> -0.64495339 | G14: =TDIST(ABS(F14),INDEX(LINEST('Daily Data'!S$4:S$3934,'Regression Inputs'!$R$5:$S$3935,TRUE(),TRUE()),4,2),2) -> 0.51899506 | K14: =INDEX(LINEST('Daily Data'!S$4:S$3934,'Regression Inputs'!$R$5:$S$3935,TRUE(),TRUE()),1,2) -> 0.33358997 | L14: =K14/INDEX(LINEST('Daily Data'!S$4:S$3934,'Regression Inputs'!$R$5:$S$3935,TRUE(),TRUE()),2,2) -> 1.1972664 | M14: =TDIST(ABS(L14),INDEX(LINEST('Daily Data'!S$4:S$3934,'Regression Inputs'!$R$5:$S$3935,TRUE(),TRUE()),4,2),2) -> 0.23127499 | N14: =INDEX(LINEST('Daily Data'!S$4:S$3934,'Regression Inputs'!$R$5:$S$3935,TRUE(),TRUE()),1,1) -> 1.4341076 | O14: =N14/INDEX(LINEST('Daily Data'!S$4:S$3934,'Regression Inputs'!$R$5:$S$3935,TRUE(),TRUE()),2,1) -> 5.1221462 | P14: =TDIST(ABS(O14),INDEX(LINEST('Daily Data'!S$4:S$3934,'Regression Inputs'!$R$5:$S$3935,TRUE(),TRUE()),4,2),2) -> 3.1658119e-07 | T14: =INDEX(LINEST('Daily Data'!S$4:S$3934,'Regression Inputs'!$R$5:$S$3935,TRUE(),TRUE()),3,1) -> 0.57625561 | U14: =1-(1-T14)*(D14-1)/(D14-2-1) -> 0.57603986 | V14: =D14*LN(2*PI())+D14*LN(INDEX(LINEST('Daily Data'!S$4:S$3934,'Regression Inputs'!$R$5:$S$3935,TRUE(),TRUE()),5,2)/D14)+D14+2*(2+1) -> -20780.986 | W14: =D14*LN(2*PI())+D14*LN(INDEX(LINEST('Daily Data'!S$4:S$3934,'Regression Inputs'!$R$5:$S$3935,TRUE(),TRUE()),5,2)/D14)+D14+LN(D14)*(2+1) -> -20762.157
A15: GDX | B15: GLD | C15: 1 | D15: =COUNT('Daily Data'!S$4:S$3934) -> 3931 | E15: =INDEX(LINEST('Daily Data'!S$4:S$3934,'Regression Inputs'!$E$5:$E$3935,TRUE(),TRUE()),1,2)*10000 -> -1.7549737 | F15: =INDEX(LINEST('Daily Data'!S$4:S$3934,'Regression Inputs'!$E$5:$E$3935,TRUE(),TRUE()),1,2)/INDEX(LINEST('Daily Data'!S$4:S$3934,'Regression Inputs'!$E$5:$E$3935,TRUE(),TRUE()),2,2) -> -0.63931743 | G15: =TDIST(ABS(F15),INDEX(LINEST('Daily Data'!S$4:S$3934,'Regression Inputs'!$E$5:$E$3935,TRUE(),TRUE()),4,2),2) -> 0.52265372 | N15: =INDEX(LINEST('Daily Data'!S$4:S$3934,'Regression Inputs'!$E$5:$E$3935,TRUE(),TRUE()),1,1) -> 1.7680664 | O15: =N15/INDEX(LINEST('Daily Data'!S$4:S$3934,'Regression Inputs'!$E$5:$E$3935,TRUE(),TRUE()),2,1) -> 73.073366 | P15: =TDIST(ABS(O15),INDEX(LINEST('Daily Data'!S$4:S$3934,'Regression Inputs'!$E$5:$E$3935,TRUE(),TRUE()),4,2),2) -> 0 | T15: =INDEX(LINEST('Daily Data'!S$4:S$3934,'Regression Inputs'!$E$5:$E$3935,TRUE(),TRUE()),3,1) -> 0.57610098 | U15: =1-(1-T15)*(D15-1)/(D15-1-1) -> 0.57599309 | V15: =D15*LN(2*PI())+D15*LN(INDEX(LINEST('Daily Data'!S$4:S$3934,'Regression Inputs'!$E$5:$E$3935,TRUE(),TRUE()),5,2)/D15)+D15+2*(1+1) -> -20781.552 | W15: =D15*LN(2*PI())+D15*LN(INDEX(LINEST('Daily Data'!S$4:S$3934,'Regression Inputs'!$E$5:$E$3935,TRUE(),TRUE()),5,2)/D15)+D15+LN(D15)*(1+1) -> -20768.999
A16: GDX | B16: IAU | C16: 1 | D16: =COUNT('Daily Data'!S$4:S$3934) -> 3931 | E16: =INDEX(LINEST('Daily Data'!S$4:S$3934,'Regression Inputs'!$C$5:$C$3935,TRUE(),TRUE()),1,2)*10000 -> -1.8074378 | F16: =INDEX(LINEST('Daily Data'!S$4:S$3934,'Regression Inputs'!$C$5:$C$3935,TRUE(),TRUE()),1,2)/INDEX(LINEST('Daily Data'!S$4:S$3934,'Regression Inputs'!$C$5:$C$3935,TRUE(),TRUE()),2,2) -> -0.65635634 | G16: =TDIST(ABS(F16),INDEX(LINEST('Daily Data'!S$4:S$3934,'Regression Inputs'!$C$5:$C$3935,TRUE(),TRUE()),4,2),2) -> 0.51163331 | K16: =INDEX(LINEST('Daily Data'!S$4:S$3934,'Regression Inputs'!$C$5:$C$3935,TRUE(),TRUE()),1,1) -> 1.7554163 | L16: =K16/INDEX(LINEST('Daily Data'!S$4:S$3934,'Regression Inputs'!$C$5:$C$3935,TRUE(),TRUE()),2,1) -> 72.674471 | M16: =TDIST(ABS(L16),INDEX(LINEST('Daily Data'!S$4:S$3934,'Regression Inputs'!$C$5:$C$3935,TRUE(),TRUE()),4,2),2) -> 0 | T16: =INDEX(LINEST('Daily Data'!S$4:S$3934,'Regression Inputs'!$C$5:$C$3935,TRUE(),TRUE()),3,1) -> 0.57342529 | U16: =1-(1-T16)*(D16-1)/(D16-1-1) -> 0.57331672 | V16: =D16*LN(2*PI())+D16*LN(INDEX(LINEST('Daily Data'!S$4:S$3934,'Regression Inputs'!$C$5:$C$3935,TRUE(),TRUE()),5,2)/D16)+D16+2*(1+1) -> -20756.817 | W16: =D16*LN(2*PI())+D16*LN(INDEX(LINEST('Daily Data'!S$4:S$3934,'Regression Inputs'!$C$5:$C$3935,TRUE(),TRUE()),5,2)/D16)+D16+LN(D16)*(1+1) -> -20744.264
A17: GDX | B17: SPY+TLT | C17: 2 | D17: =COUNT('Daily Data'!S$4:S$3934) -> 3931 | E17: =INDEX(LINEST('Daily Data'!S$4:S$3934,'Regression Inputs'!$O$5:$P$3935,TRUE(),TRUE()),1,3)*10000 -> -1.6922723 | F17: =INDEX(LINEST('Daily Data'!S$4:S$3934,'Regression Inputs'!$O$5:$P$3935,TRUE(),TRUE()),1,3)/INDEX(LINEST('Daily Data'!S$4:S$3934,'Regression Inputs'!$O$5:$P$3935,TRUE(),TRUE()),2,3) -> -0.42178048 | G17: =TDIST(ABS(F17),INDEX(LINEST('Daily Data'!S$4:S$3934,'Regression Inputs'!$O$5:$P$3935,TRUE(),TRUE()),4,2),2) -> 0.67320834 | H17: =INDEX(LINEST('Daily Data'!S$4:S$3934,'Regression Inputs'!$O$5:$P$3935,TRUE(),TRUE()),1,2) -> 0.72927029 | I17: =H17/INDEX(LINEST('Daily Data'!S$4:S$3934,'Regression Inputs'!$O$5:$P$3935,TRUE(),TRUE()),2,2) -> 20.479595 | J17: =TDIST(ABS(I17),INDEX(LINEST('Daily Data'!S$4:S$3934,'Regression Inputs'!$O$5:$P$3935,TRUE(),TRUE()),4,2),2) -> 1.198755e-88 | Q17: =INDEX(LINEST('Daily Data'!S$4:S$3934,'Regression Inputs'!$O$5:$P$3935,TRUE(),TRUE()),1,1) -> 0.5193015 | R17: =Q17/INDEX(LINEST('Daily Data'!S$4:S$3934,'Regression Inputs'!$O$5:$P$3935,TRUE(),TRUE()),2,1) -> 10.7162 | S17: =TDIST(ABS(R17),INDEX(LINEST('Daily Data'!S$4:S$3934,'Regression Inputs'!$O$5:$P$3935,TRUE(),TRUE()),4,2),2) -> 1.9745483e-26 | T17: =INDEX(LINEST('Daily Data'!S$4:S$3934,'Regression Inputs'!$O$5:$P$3935,TRUE(),TRUE()),3,1) -> 0.097497078 | U17: =1-(1-T17)*(D17-1)/(D17-2-1) -> 0.097037555 | V17: =D17*LN(2*PI())+D17*LN(INDEX(LINEST('Daily Data'!S$4:S$3934,'Regression Inputs'!$O$5:$P$3935,TRUE(),TRUE()),5,2)/D17)+D17+2*(2+1) -> -17808.987 | W17: =D17*LN(2*PI())+D17*LN(INDEX(LINEST('Daily Data'!S$4:S$3934,'Regression Inputs'!$O$5:$P$3935,TRUE(),TRUE()),5,2)/D17)+D17+LN(D17)*(2+1) -> -17790.157
A18: GDX | B18: SPY | C18: 1 | D18: =COUNT('Daily Data'!S$4:S$3934) -> 3931 | E18: =INDEX(LINEST('Daily Data'!S$4:S$3934,'Regression Inputs'!$A$5:$A$3935,TRUE(),TRUE()),1,2)*10000 -> 0.40237146 | F18: =INDEX(LINEST('Daily Data'!S$4:S$3934,'Regression Inputs'!$A$5:$A$3935,TRUE(),TRUE()),1,2)/INDEX(LINEST('Daily Data'!S$4:S$3934,'Regression Inputs'!$A$5:$A$3935,TRUE(),TRUE()),2,2) -> 0.098982243 | G18: =TDIST(ABS(F18),INDEX(LINEST('Daily Data'!S$4:S$3934,'Regression Inputs'!$A$5:$A$3935,TRUE(),TRUE()),4,2),2) -> 0.92115742 | H18: =INDEX(LINEST('Daily Data'!S$4:S$3934,'Regression Inputs'!$A$5:$A$3935,TRUE(),TRUE()),1,1) -> 0.56702769 | I18: =H18/INDEX(LINEST('Daily Data'!S$4:S$3934,'Regression Inputs'!$A$5:$A$3935,TRUE(),TRUE()),2,1) -> 17.343259 | J18: =TDIST(ABS(I18),INDEX(LINEST('Daily Data'!S$4:S$3934,'Regression Inputs'!$A$5:$A$3935,TRUE(),TRUE()),4,2),2) -> 5.5130758e-65 | T18: =INDEX(LINEST('Daily Data'!S$4:S$3934,'Regression Inputs'!$A$5:$A$3935,TRUE(),TRUE()),3,1) -> 0.071111979 | U18: =1-(1-T18)*(D18-1)/(D18-1-1) -> 0.07087556 | V18: =D18*LN(2*PI())+D18*LN(INDEX(LINEST('Daily Data'!S$4:S$3934,'Regression Inputs'!$A$5:$A$3935,TRUE(),TRUE()),5,2)/D18)+D18+2*(1+1) -> -17697.711 | W18: =D18*LN(2*PI())+D18*LN(INDEX(LINEST('Daily Data'!S$4:S$3934,'Regression Inputs'!$A$5:$A$3935,TRUE(),TRUE()),5,2)/D18)+D18+LN(D18)*(1+1) -> -17685.157
A19: GDX | B19: TLT | C19: 1 | D19: =COUNT('Daily Data'!S$4:S$3934) -> 3931 | E19: =INDEX(LINEST('Daily Data'!S$4:S$3934,'Regression Inputs'!$G$5:$G$3935,TRUE(),TRUE()),1,2)*10000 -> 2.7006747 | F19: =INDEX(LINEST('Daily Data'!S$4:S$3934,'Regression Inputs'!$G$5:$G$3935,TRUE(),TRUE()),1,2)/INDEX(LINEST('Daily Data'!S$4:S$3934,'Regression Inputs'!$G$5:$G$3935,TRUE(),TRUE()),2,2) -> 0.6408193 | G19: =TDIST(ABS(F19),INDEX(LINEST('Daily Data'!S$4:S$3934,'Regression Inputs'!$G$5:$G$3935,TRUE(),TRUE()),4,2),2) -> 0.52167747 | Q19: =INDEX(LINEST('Daily Data'!S$4:S$3934,'Regression Inputs'!$G$5:$G$3935,TRUE(),TRUE()),1,1) -> 0.097355302 | R19: =Q19/INDEX(LINEST('Daily Data'!S$4:S$3934,'Regression Inputs'!$G$5:$G$3935,TRUE(),TRUE()),2,1) -> 2.1100952 | S19: =TDIST(ABS(R19),INDEX(LINEST('Daily Data'!S$4:S$3934,'Regression Inputs'!$G$5:$G$3935,TRUE(),TRUE()),4,2),2) -> 0.034913215 | T19: =INDEX(LINEST('Daily Data'!S$4:S$3934,'Regression Inputs'!$G$5:$G$3935,TRUE(),TRUE()),3,1) -> 0.0011319577 | U19: =1-(1-T19)*(D19-1)/(D19-1-1) -> 0.00087772807 | V19: =D19*LN(2*PI())+D19*LN(INDEX(LINEST('Daily Data'!S$4:S$3934,'Regression Inputs'!$G$5:$G$3935,TRUE(),TRUE()),5,2)/D19)+D19+2*(1+1) -> -17412.184 | W19: =D19*LN(2*PI())+D19*LN(INDEX(LINEST('Daily Data'!S$4:S$3934,'Regression Inputs'!$G$5:$G$3935,TRUE(),TRUE()),5,2)/D19)+D19+LN(D19)*(1+1) -> -17399.631
A20: GDXJ | B20: SPY+GLD | C20: 2 | D20: =COUNT('Daily Data'!T$880:T$3934) -> 3055 | E20: =INDEX(LINEST('Daily Data'!T$880:T$3934,'Regression Inputs'!$L$881:$M$3935,TRUE(),TRUE()),1,3)*10000 -> -4.9263035 | F20: =INDEX(LINEST('Daily Data'!T$880:T$3934,'Regression Inputs'!$L$881:$M$3935,TRUE(),TRUE()),1,3)/INDEX(LINEST('Daily Data'!T$880:T$3934,'Regression Inputs'!$L$881:$M$3935,TRUE(),TRUE()),2,3) -> -1.4536498 | G20: =TDIST(ABS(F20),INDEX(LINEST('Daily Data'!T$880:T$3934,'Regression Inputs'!$L$881:$M$3935,TRUE(),TRUE()),4,2),2) -> 0.14614623 | H20: =INDEX(LINEST('Daily Data'!T$880:T$3934,'Regression Inputs'!$L$881:$M$3935,TRUE(),TRUE()),1,2) -> 0.55743268 | I20: =H20/INDEX(LINEST('Daily Data'!T$880:T$3934,'Regression Inputs'!$L$881:$M$3935,TRUE(),TRUE()),2,2) -> 17.506686 | J20: =TDIST(ABS(I20),INDEX(LINEST('Daily Data'!T$880:T$3934,'Regression Inputs'!$L$881:$M$3935,TRUE(),TRUE()),4,2),2) -> 1.8172238e-65 | N20: =INDEX(LINEST('Daily Data'!T$880:T$3934,'Regression Inputs'!$L$881:$M$3935,TRUE(),TRUE()),1,1) -> 2.1631406 | O20: =N20/INDEX(LINEST('Daily Data'!T$880:T$3934,'Regression Inputs'!$L$881:$M$3935,TRUE(),TRUE()),2,1) -> 63.629482 | P20: =TDIST(ABS(O20),INDEX(LINEST('Daily Data'!T$880:T$3934,'Regression Inputs'!$L$881:$M$3935,TRUE(),TRUE()),4,2),2) -> 0 | T20: =INDEX(LINEST('Daily Data'!T$880:T$3934,'Regression Inputs'!$L$881:$M$3935,TRUE(),TRUE()),3,1) -> 0.59268824 | U20: =1-(1-T20)*(D20-1)/(D20-2-1) -> 0.59242132 | V20: =D20*LN(2*PI())+D20*LN(INDEX(LINEST('Daily Data'!T$880:T$3934,'Regression Inputs'!$L$881:$M$3935,TRUE(),TRUE()),5,2)/D20)+D20+2*(2+1) -> -15640.351 | W20: =D20*LN(2*PI())+D20*LN(INDEX(LINEST('Daily Data'!T$880:T$3934,'Regression Inputs'!$L$881:$M$3935,TRUE(),TRUE()),5,2)/D20)+D20+LN(D20)*(2+1) -> -15622.277
A21: GDXJ | B21: SPY+IAU+GLD | C21: 3 | D21: =COUNT('Daily Data'!T$880:T$3934) -> 3055 | E21: =INDEX(LINEST('Daily Data'!T$880:T$3934,'Regression Inputs'!$AA$881:$AC$3935,TRUE(),TRUE()),1,4)*10000 -> -4.9017954 | F21: =INDEX(LINEST('Daily Data'!T$880:T$3934,'Regression Inputs'!$AA$881:$AC$3935,TRUE(),TRUE()),1,4)/INDEX(LINEST('Daily Data'!T$880:T$3934,'Regression Inputs'!$AA$881:$AC$3935,TRUE(),TRUE()),2,4) -> -1.4462067 | G21: =TDIST(ABS(F21),INDEX(LINEST('Daily Data'!T$880:T$3934,'Regression Inputs'!$AA$881:$AC$3935,TRUE(),TRUE()),4,2),2) -> 0.14822195 | H21: =INDEX(LINEST('Daily Data'!T$880:T$3934,'Regression Inputs'!$AA$881:$AC$3935,TRUE(),TRUE()),1,3) -> 0.55723948 | I21: =H21/INDEX(LINEST('Daily Data'!T$880:T$3934,'Regression Inputs'!$AA$881:$AC$3935,TRUE(),TRUE()),2,3) -> 17.498357 | J21: =TDIST(ABS(I21),INDEX(LINEST('Daily Data'!T$880:T$3934,'Regression Inputs'!$AA$881:$AC$3935,TRUE(),TRUE()),4,2),2) -> 2.0801434e-65 | K21: =INDEX(LINEST('Daily Data'!T$880:T$3934,'Regression Inputs'!$AA$881:$AC$3935,TRUE(),TRUE()),1,2) -> -0.41125008 | L21: =K21/INDEX(LINEST('Daily Data'!T$880:T$3934,'Regression Inputs'!$AA$881:$AC$3935,TRUE(),TRUE()),2,2) -> -0.67619256 | M21: =TDIST(ABS(L21),INDEX(LINEST('Daily Data'!T$880:T$3934,'Regression Inputs'!$AA$881:$AC$3935,TRUE(),TRUE()),4,2),2) -> 0.49896965 | N21: =INDEX(LINEST('Daily Data'!T$880:T$3934,'Regression Inputs'!$AA$881:$AC$3935,TRUE(),TRUE()),1,1) -> 2.5741002 | O21: =N21/INDEX(LINEST('Daily Data'!T$880:T$3934,'Regression Inputs'!$AA$881:$AC$3935,TRUE(),TRUE()),2,1) -> 4.2288105 | P21: =TDIST(ABS(O21),INDEX(LINEST('Daily Data'!T$880:T$3934,'Regression Inputs'!$AA$881:$AC$3935,TRUE(),TRUE()),4,2),2) -> 2.4183515e-05 | T21: =INDEX(LINEST('Daily Data'!T$880:T$3934,'Regression Inputs'!$AA$881:$AC$3935,TRUE(),TRUE()),3,1) -> 0.59274927 | U21: =1-(1-T21)*(D21-1)/(D21-3-1) -> 0.59234883 | V21: =D21*LN(2*PI())+D21*LN(INDEX(LINEST('Daily Data'!T$880:T$3934,'Regression Inputs'!$AA$881:$AC$3935,TRUE(),TRUE()),5,2)/D21)+D21+2*(3+1) -> -15638.809 | W21: =D21*LN(2*PI())+D21*LN(INDEX(LINEST('Daily Data'!T$880:T$3934,'Regression Inputs'!$AA$881:$AC$3935,TRUE(),TRUE()),5,2)/D21)+D21+LN(D21)*(3+1) -> -15614.71
A22: GDXJ | B22: SPY+GLD+TLT | C22: 3 | D22: =COUNT('Daily Data'!T$880:T$3934) -> 3055 | E22: =INDEX(LINEST('Daily Data'!T$880:T$3934,'Regression Inputs'!$AI$881:$AK$3935,TRUE(),TRUE()),1,4)*10000 -> -5.0252928 | F22: =INDEX(LINEST('Daily Data'!T$880:T$3934,'Regression Inputs'!$AI$881:$AK$3935,TRUE(),TRUE()),1,4)/INDEX(LINEST('Daily Data'!T$880:T$3934,'Regression Inputs'!$AI$881:$AK$3935,TRUE(),TRUE()),2,4) -> -1.4799345 | G22: =TDIST(ABS(F22),INDEX(LINEST('Daily Data'!T$880:T$3934,'Regression Inputs'!$AI$881:$AK$3935,TRUE(),TRUE()),4,2),2) -> 0.13899397 | H22: =INDEX(LINEST('Daily Data'!T$880:T$3934,'Regression Inputs'!$AI$881:$AK$3935,TRUE(),TRUE()),1,3) -> 0.56570631 | I22: =H22/INDEX(LINEST('Daily Data'!T$880:T$3934,'Regression Inputs'!$AI$881:$AK$3935,TRUE(),TRUE()),2,3) -> 15.621949 | J22: =TDIST(ABS(I22),INDEX(LINEST('Daily Data'!T$880:T$3934,'Regression Inputs'!$AI$881:$AK$3935,TRUE(),TRUE()),4,2),2) -> 5.5228161e-53 | N22: =INDEX(LINEST('Daily Data'!T$880:T$3934,'Regression Inputs'!$AI$881:$AK$3935,TRUE(),TRUE()),1,2) -> 2.1589713 | O22: =N22/INDEX(LINEST('Daily Data'!T$880:T$3934,'Regression Inputs'!$AI$881:$AK$3935,TRUE(),TRUE()),2,2) -> 61.522151 | P22: =TDIST(ABS(O22),INDEX(LINEST('Daily Data'!T$880:T$3934,'Regression Inputs'!$AI$881:$AK$3935,TRUE(),TRUE()),4,2),2) -> 0 | Q22: =INDEX(LINEST('Daily Data'!T$880:T$3934,'Regression Inputs'!$AI$881:$AK$3935,TRUE(),TRUE()),1,1) -> 0.020769229 | R22: =Q22/INDEX(LINEST('Daily Data'!T$880:T$3934,'Regression Inputs'!$AI$881:$AK$3935,TRUE(),TRUE()),2,1) -> 0.47991061 | S22: =TDIST(ABS(R22),INDEX(LINEST('Daily Data'!T$880:T$3934,'Regression Inputs'!$AI$881:$AK$3935,TRUE(),TRUE()),4,2),2) -> 0.63132536 | T22: =INDEX(LINEST('Daily Data'!T$880:T$3934,'Regression Inputs'!$AI$881:$AK$3935,TRUE(),TRUE()),3,1) -> 0.59271898 | U22: =1-(1-T22)*(D22-1)/(D22-3-1) -> 0.59231851 | V22: =D22*LN(2*PI())+D22*LN(INDEX(LINEST('Daily Data'!T$880:T$3934,'Regression Inputs'!$AI$881:$AK$3935,TRUE(),TRUE()),5,2)/D22)+D22+2*(3+1) -> -15638.581 | W22: =D22*LN(2*PI())+D22*LN(INDEX(LINEST('Daily Data'!T$880:T$3934,'Regression Inputs'!$AI$881:$AK$3935,TRUE(),TRUE()),5,2)/D22)+D22+LN(D22)*(3+1) -> -15614.483
A23: GDXJ | B23: SPY+IAU+GLD+TLT | C23: 4 | D23: =COUNT('Daily Data'!T$880:T$3934) -> 3055 | E23: =INDEX(LINEST('Daily Data'!T$880:T$3934,'Regression Inputs'!$AQ$881:$AT$3935,TRUE(),TRUE()),1,5)*10000 -> -4.9967361 | F23: =INDEX(LINEST('Daily Data'!T$880:T$3934,'Regression Inputs'!$AQ$881:$AT$3935,TRUE(),TRUE()),1,5)/INDEX(LINEST('Daily Data'!T$880:T$3934,'Regression Inputs'!$AQ$881:$AT$3935,TRUE(),TRUE()),2,5) -> -1.4712693 | G23: =TDIST(ABS(F23),INDEX(LINEST('Daily Data'!T$880:T$3934,'Regression Inputs'!$AQ$881:$AT$3935,TRUE(),TRUE()),4,2),2) -> 0.14132146 | H23: =INDEX(LINEST('Daily Data'!T$880:T$3934,'Regression Inputs'!$AQ$881:$AT$3935,TRUE(),TRUE()),1,4) -> 0.56513226 | I23: =H23/INDEX(LINEST('Daily Data'!T$880:T$3934,'Regression Inputs'!$AQ$881:$AT$3935,TRUE(),TRUE()),2,4) -> 15.600158 | J23: =TDIST(ABS(I23),INDEX(LINEST('Daily Data'!T$880:T$3934,'Regression Inputs'!$AQ$881:$AT$3935,TRUE(),TRUE()),4,2),2) -> 7.5884307e-53 | K23: =INDEX(LINEST('Daily Data'!T$880:T$3934,'Regression Inputs'!$AQ$881:$AT$3935,TRUE(),TRUE()),1,3) -> -0.40183674 | L23: =K23/INDEX(LINEST('Daily Data'!T$880:T$3934,'Regression Inputs'!$AQ$881:$AT$3935,TRUE(),TRUE()),2,3) -> -0.66025113 | M23: =TDIST(ABS(L23),INDEX(LINEST('Daily Data'!T$880:T$3934,'Regression Inputs'!$AQ$881:$AT$3935,TRUE(),TRUE()),4,2),2) -> 0.50914255 | N23: =INDEX(LINEST('Daily Data'!T$880:T$3934,'Regression Inputs'!$AQ$881:$AT$3935,TRUE(),TRUE()),1,2) -> 2.5607183 | O23: =N23/INDEX(LINEST('Daily Data'!T$880:T$3934,'Regression Inputs'!$AQ$881:$AT$3935,TRUE(),TRUE()),2,2) -> 4.2014292 | P23: =TDIST(ABS(O23),INDEX(LINEST('Daily Data'!T$880:T$3934,'Regression Inputs'!$AQ$881:$AT$3935,TRUE(),TRUE()),4,2),2) -> 2.7284085e-05 | Q23: =INDEX(LINEST('Daily Data'!T$880:T$3934,'Regression Inputs'!$AQ$881:$AT$3935,TRUE(),TRUE()),1,1) -> 0.019802067 | R23: =Q23/INDEX(LINEST('Daily Data'!T$880:T$3934,'Regression Inputs'!$AQ$881:$AT$3935,TRUE(),TRUE()),2,1) -> 0.45725847 | S23: =TDIST(ABS(R23),INDEX(LINEST('Daily Data'!T$880:T$3934,'Regression Inputs'!$AQ$881:$AT$3935,TRUE(),TRUE()),4,2),2) -> 0.64751784 | T23: =INDEX(LINEST('Daily Data'!T$880:T$3934,'Regression Inputs'!$AQ$881:$AT$3935,TRUE(),TRUE()),3,1) -> 0.59277719 | U23: =1-(1-T23)*(D23-1)/(D23-4-1) -> 0.59224312 | V23: =D23*LN(2*PI())+D23*LN(INDEX(LINEST('Daily Data'!T$880:T$3934,'Regression Inputs'!$AQ$881:$AT$3935,TRUE(),TRUE()),5,2)/D23)+D23+2*(4+1) -> -15637.018 | W23: =D23*LN(2*PI())+D23*LN(INDEX(LINEST('Daily Data'!T$880:T$3934,'Regression Inputs'!$AQ$881:$AT$3935,TRUE(),TRUE()),5,2)/D23)+D23+LN(D23)*(4+1) -> -15606.895
A24: GDXJ | B24: SPY+IAU | C24: 2 | D24: =COUNT('Daily Data'!T$880:T$3934) -> 3055 | E24: =INDEX(LINEST('Daily Data'!T$880:T$3934,'Regression Inputs'!$I$881:$J$3935,TRUE(),TRUE()),1,3)*10000 -> -5.0424728 | F24: =INDEX(LINEST('Daily Data'!T$880:T$3934,'Regression Inputs'!$I$881:$J$3935,TRUE(),TRUE()),1,3)/INDEX(LINEST('Daily Data'!T$880:T$3934,'Regression Inputs'!$I$881:$J$3935,TRUE(),TRUE()),2,3) -> -1.4836852 | G24: =TDIST(ABS(F24),INDEX(LINEST('Daily Data'!T$880:T$3934,'Regression Inputs'!$I$881:$J$3935,TRUE(),TRUE()),4,2),2) -> 0.1379957 | H24: =INDEX(LINEST('Daily Data'!T$880:T$3934,'Regression Inputs'!$I$881:$J$3935,TRUE(),TRUE()),1,2) -> 0.55871625 | I24: =H24/INDEX(LINEST('Daily Data'!T$880:T$3934,'Regression Inputs'!$I$881:$J$3935,TRUE(),TRUE()),2,2) -> 17.497457 | J24: =TDIST(ABS(I24),INDEX(LINEST('Daily Data'!T$880:T$3934,'Regression Inputs'!$I$881:$J$3935,TRUE(),TRUE()),4,2),2) -> 2.105543e-65 | K24: =INDEX(LINEST('Daily Data'!T$880:T$3934,'Regression Inputs'!$I$881:$J$3935,TRUE(),TRUE()),1,1) -> 2.1566335 | L24: =K24/INDEX(LINEST('Daily Data'!T$880:T$3934,'Regression Inputs'!$I$881:$J$3935,TRUE(),TRUE()),2,1) -> 63.311863 | M24: =TDIST(ABS(L24),INDEX(LINEST('Daily Data'!T$880:T$3934,'Regression Inputs'!$I$881:$J$3935,TRUE(),TRUE()),4,2),2) -> 0 | T24: =INDEX(LINEST('Daily Data'!T$880:T$3934,'Regression Inputs'!$I$881:$J$3935,TRUE(),TRUE()),3,1) -> 0.59036225 | U24: =1-(1-T24)*(D24-1)/(D24-2-1) -> 0.59009381 | V24: =D24*LN(2*PI())+D24*LN(INDEX(LINEST('Daily Data'!T$880:T$3934,'Regression Inputs'!$I$881:$J$3935,TRUE(),TRUE()),5,2)/D24)+D24+2*(2+1) -> -15622.955 | W24: =D24*LN(2*PI())+D24*LN(INDEX(LINEST('Daily Data'!T$880:T$3934,'Regression Inputs'!$I$881:$J$3935,TRUE(),TRUE()),5,2)/D24)+D24+LN(D24)*(2+1) -> -15604.881
A25: GDXJ | B25: SPY+IAU+TLT | C25: 3 | D25: =COUNT('Daily Data'!T$880:T$3934) -> 3055 | E25: =INDEX(LINEST('Daily Data'!T$880:T$3934,'Regression Inputs'!$AE$881:$AG$3935,TRUE(),TRUE()),1,4)*10000 -> -5.1782464 | F25: =INDEX(LINEST('Daily Data'!T$880:T$3934,'Regression Inputs'!$AE$881:$AG$3935,TRUE(),TRUE()),1,4)/INDEX(LINEST('Daily Data'!T$880:T$3934,'Regression Inputs'!$AE$881:$AG$3935,TRUE(),TRUE()),2,4) -> -1.5206934 | G25: =TDIST(ABS(F25),INDEX(LINEST('Daily Data'!T$880:T$3934,'Regression Inputs'!$AE$881:$AG$3935,TRUE(),TRUE()),4,2),2) -> 0.12844041 | H25: =INDEX(LINEST('Daily Data'!T$880:T$3934,'Regression Inputs'!$AE$881:$AG$3935,TRUE(),TRUE()),1,3) -> 0.57008018 | I25: =H25/INDEX(LINEST('Daily Data'!T$880:T$3934,'Regression Inputs'!$AE$881:$AG$3935,TRUE(),TRUE()),2,3) -> 15.702273 | J25: =TDIST(ABS(I25),INDEX(LINEST('Daily Data'!T$880:T$3934,'Regression Inputs'!$AE$881:$AG$3935,TRUE(),TRUE()),4,2),2) -> 1.7155856e-53 | K25: =INDEX(LINEST('Daily Data'!T$880:T$3934,'Regression Inputs'!$AE$881:$AG$3935,TRUE(),TRUE()),1,2) -> 2.1509606 | L25: =K25/INDEX(LINEST('Daily Data'!T$880:T$3934,'Regression Inputs'!$AE$881:$AG$3935,TRUE(),TRUE()),2,2) -> 61.209564 | M25: =TDIST(ABS(L25),INDEX(LINEST('Daily Data'!T$880:T$3934,'Regression Inputs'!$AE$881:$AG$3935,TRUE(),TRUE()),4,2),2) -> 0 | Q25: =INDEX(LINEST('Daily Data'!T$880:T$3934,'Regression Inputs'!$AE$881:$AG$3935,TRUE(),TRUE()),1,1) -> 0.028538553 | R25: =Q25/INDEX(LINEST('Daily Data'!T$880:T$3934,'Regression Inputs'!$AE$881:$AG$3935,TRUE(),TRUE()),2,1) -> 0.65796453 | S25: =TDIST(ABS(R25),INDEX(LINEST('Daily Data'!T$880:T$3934,'Regression Inputs'!$AE$881:$AG$3935,TRUE(),TRUE()),4,2),2) -> 0.51061056 | T25: =INDEX(LINEST('Daily Data'!T$880:T$3934,'Regression Inputs'!$AE$881:$AG$3935,TRUE(),TRUE()),3,1) -> 0.59042037 | U25: =1-(1-T25)*(D25-1)/(D25-3-1) -> 0.59001763 | V25: =D25*LN(2*PI())+D25*LN(INDEX(LINEST('Daily Data'!T$880:T$3934,'Regression Inputs'!$AE$881:$AG$3935,TRUE(),TRUE()),5,2)/D25)+D25+2*(3+1) -> -15621.388 | W25: =D25*LN(2*PI())+D25*LN(INDEX(LINEST('Daily Data'!T$880:T$3934,'Regression Inputs'!$AE$881:$AG$3935,TRUE(),TRUE()),5,2)/D25)+D25+LN(D25)*(3+1) -> -15597.29
A26: GDXJ | B26: GLD+TLT | C26: 2 | D26: =COUNT('Daily Data'!T$880:T$3934) -> 3055 | E26: =INDEX(LINEST('Daily Data'!T$880:T$3934,'Regression Inputs'!$X$881:$Y$3935,TRUE(),TRUE()),1,3)*10000 -> -0.93337822 | F26: =INDEX(LINEST('Daily Data'!T$880:T$3934,'Regression Inputs'!$X$881:$Y$3935,TRUE(),TRUE()),1,3)/INDEX(LINEST('Daily Data'!T$880:T$3934,'Regression Inputs'!$X$881:$Y$3935,TRUE(),TRUE()),2,3) -> -0.26533609 | G26: =TDIST(ABS(F26),INDEX(LINEST('Daily Data'!T$880:T$3934,'Regression Inputs'!$X$881:$Y$3935,TRUE(),TRUE()),4,2),2) -> 0.79076848 | N26: =INDEX(LINEST('Daily Data'!T$880:T$3934,'Regression Inputs'!$X$881:$Y$3935,TRUE(),TRUE()),1,2) -> 2.2403778 | O26: =N26/INDEX(LINEST('Daily Data'!T$880:T$3934,'Regression Inputs'!$X$881:$Y$3935,TRUE(),TRUE()),2,2) -> 62.131131 | P26: =TDIST(ABS(O26),INDEX(LINEST('Daily Data'!T$880:T$3934,'Regression Inputs'!$X$881:$Y$3935,TRUE(),TRUE()),4,2),2) -> 0 | Q26: =INDEX(LINEST('Daily Data'!T$880:T$3934,'Regression Inputs'!$X$881:$Y$3935,TRUE(),TRUE()),1,1) -> -0.30109679 | R26: =Q26/INDEX(LINEST('Daily Data'!T$880:T$3934,'Regression Inputs'!$X$881:$Y$3935,TRUE(),TRUE()),2,1) -> -7.614129 | S26: =TDIST(ABS(R26),INDEX(LINEST('Daily Data'!T$880:T$3934,'Regression Inputs'!$X$881:$Y$3935,TRUE(),TRUE()),4,2),2) -> 3.5168682e-14 | T26: =INDEX(LINEST('Daily Data'!T$880:T$3934,'Regression Inputs'!$X$881:$Y$3935,TRUE(),TRUE()),3,1) -> 0.56014114 | U26: =1-(1-T26)*(D26-1)/(D26-2-1) -> 0.55985289 | V26: =D26*LN(2*PI())+D26*LN(INDEX(LINEST('Daily Data'!T$880:T$3934,'Regression Inputs'!$X$881:$Y$3935,TRUE(),TRUE()),5,2)/D26)+D26+2*(2+1) -> -15405.498 | W26: =D26*LN(2*PI())+D26*LN(INDEX(LINEST('Daily Data'!T$880:T$3934,'Regression Inputs'!$X$881:$Y$3935,TRUE(),TRUE()),5,2)/D26)+D26+LN(D26)*(2+1) -> -15387.424
A27: GDXJ | B27: IAU+GLD+TLT | C27: 3 | D27: =COUNT('Daily Data'!T$880:T$3934) -> 3055 | E27: =INDEX(LINEST('Daily Data'!T$880:T$3934,'Regression Inputs'!$AM$881:$AO$3935,TRUE(),TRUE()),1,4)*10000 -> -0.8951346 | F27: =INDEX(LINEST('Daily Data'!T$880:T$3934,'Regression Inputs'!$AM$881:$AO$3935,TRUE(),TRUE()),1,4)/INDEX(LINEST('Daily Data'!T$880:T$3934,'Regression Inputs'!$AM$881:$AO$3935,TRUE(),TRUE()),2,4) -> -0.25444892 | G27: =TDIST(ABS(F27),INDEX(LINEST('Daily Data'!T$880:T$3934,'Regression Inputs'!$AM$881:$AO$3935,TRUE(),TRUE()),4,2),2) -> 0.79916591 | K27: =INDEX(LINEST('Daily Data'!T$880:T$3934,'Regression Inputs'!$AM$881:$AO$3935,TRUE(),TRUE()),1,3) -> -0.62971032 | L27: =K27/INDEX(LINEST('Daily Data'!T$880:T$3934,'Regression Inputs'!$AM$881:$AO$3935,TRUE(),TRUE()),2,3) -> -0.99615429 | M27: =TDIST(ABS(L27),INDEX(LINEST('Daily Data'!T$880:T$3934,'Regression Inputs'!$AM$881:$AO$3935,TRUE(),TRUE()),4,2),2) -> 0.31925418 | N27: =INDEX(LINEST('Daily Data'!T$880:T$3934,'Regression Inputs'!$AM$881:$AO$3935,TRUE(),TRUE()),1,2) -> 2.8698181 | O27: =N27/INDEX(LINEST('Daily Data'!T$880:T$3934,'Regression Inputs'!$AM$881:$AO$3935,TRUE(),TRUE()),2,2) -> 4.534406 | P27: =TDIST(ABS(O27),INDEX(LINEST('Daily Data'!T$880:T$3934,'Regression Inputs'!$AM$881:$AO$3935,TRUE(),TRUE()),4,2),2) -> 5.9990249e-06 | Q27: =INDEX(LINEST('Daily Data'!T$880:T$3934,'Regression Inputs'!$AM$881:$AO$3935,TRUE(),TRUE()),1,1) -> -0.30210057 | R27: =Q27/INDEX(LINEST('Daily Data'!T$880:T$3934,'Regression Inputs'!$AM$881:$AO$3935,TRUE(),TRUE()),2,1) -> -7.6370241 | S27: =TDIST(ABS(R27),INDEX(LINEST('Daily Data'!T$880:T$3934,'Regression Inputs'!$AM$881:$AO$3935,TRUE(),TRUE()),4,2),2) -> 2.9549689e-14 | T27: =INDEX(LINEST('Daily Data'!T$880:T$3934,'Regression Inputs'!$AM$881:$AO$3935,TRUE(),TRUE()),3,1) -> 0.56028415 | U27: =1-(1-T27)*(D27-1)/(D27-3-1) -> 0.55985178 | V27: =D27*LN(2*PI())+D27*LN(INDEX(LINEST('Daily Data'!T$880:T$3934,'Regression Inputs'!$AM$881:$AO$3935,TRUE(),TRUE()),5,2)/D27)+D27+2*(3+1) -> -15404.491 | W27: =D27*LN(2*PI())+D27*LN(INDEX(LINEST('Daily Data'!T$880:T$3934,'Regression Inputs'!$AM$881:$AO$3935,TRUE(),TRUE()),5,2)/D27)+D27+LN(D27)*(3+1) -> -15380.393
A28: GDXJ | B28: IAU+TLT | C28: 2 | D28: =COUNT('Daily Data'!T$880:T$3934) -> 3055 | E28: =INDEX(LINEST('Daily Data'!T$880:T$3934,'Regression Inputs'!$U$881:$V$3935,TRUE(),TRUE()),1,3)*10000 -> -1.0584817 | F28: =INDEX(LINEST('Daily Data'!T$880:T$3934,'Regression Inputs'!$U$881:$V$3935,TRUE(),TRUE()),1,3)/INDEX(LINEST('Daily Data'!T$880:T$3934,'Regression Inputs'!$U$881:$V$3935,TRUE(),TRUE()),2,3) -> -0.29993771 | G28: =TDIST(ABS(F28),INDEX(LINEST('Daily Data'!T$880:T$3934,'Regression Inputs'!$U$881:$V$3935,TRUE(),TRUE()),4,2),2) -> 0.76424509 | K28: =INDEX(LINEST('Daily Data'!T$880:T$3934,'Regression Inputs'!$U$881:$V$3935,TRUE(),TRUE()),1,2) -> 2.2320192 | L28: =K28/INDEX(LINEST('Daily Data'!T$880:T$3934,'Regression Inputs'!$U$881:$V$3935,TRUE(),TRUE()),2,2) -> 61.775725 | M28: =TDIST(ABS(L28),INDEX(LINEST('Daily Data'!T$880:T$3934,'Regression Inputs'!$U$881:$V$3935,TRUE(),TRUE()),4,2),2) -> 0 | Q28: =INDEX(LINEST('Daily Data'!T$880:T$3934,'Regression Inputs'!$U$881:$V$3935,TRUE(),TRUE()),1,1) -> -0.29546107 | R28: =Q28/INDEX(LINEST('Daily Data'!T$880:T$3934,'Regression Inputs'!$U$881:$V$3935,TRUE(),TRUE()),2,1) -> -7.4504639 | S28: =TDIST(ABS(R28),INDEX(LINEST('Daily Data'!T$880:T$3934,'Regression Inputs'!$U$881:$V$3935,TRUE(),TRUE()),4,2),2) -> 1.2042846e-13 | T28: =INDEX(LINEST('Daily Data'!T$880:T$3934,'Regression Inputs'!$U$881:$V$3935,TRUE(),TRUE()),3,1) -> 0.55732088 | U28: =1-(1-T28)*(D28-1)/(D28-2-1) -> 0.55703079 | V28: =D28*LN(2*PI())+D28*LN(INDEX(LINEST('Daily Data'!T$880:T$3934,'Regression Inputs'!$U$881:$V$3935,TRUE(),TRUE()),5,2)/D28)+D28+2*(2+1) -> -15385.972 | W28: =D28*LN(2*PI())+D28*LN(INDEX(LINEST('Daily Data'!T$880:T$3934,'Regression Inputs'!$U$881:$V$3935,TRUE(),TRUE()),5,2)/D28)+D28+LN(D28)*(2+1) -> -15367.899
A29: GDXJ | B29: GLD | C29: 1 | D29: =COUNT('Daily Data'!T$880:T$3934) -> 3055 | E29: =INDEX(LINEST('Daily Data'!T$880:T$3934,'Regression Inputs'!$E$881:$E$3935,TRUE(),TRUE()),1,2)*10000 -> -1.6671727 | F29: =INDEX(LINEST('Daily Data'!T$880:T$3934,'Regression Inputs'!$E$881:$E$3935,TRUE(),TRUE()),1,2)/INDEX(LINEST('Daily Data'!T$880:T$3934,'Regression Inputs'!$E$881:$E$3935,TRUE(),TRUE()),2,2) -> -0.46975051 | G29: =TDIST(ABS(F29),INDEX(LINEST('Daily Data'!T$880:T$3934,'Regression Inputs'!$E$881:$E$3935,TRUE(),TRUE()),4,2),2) -> 0.63856682 | N29: =INDEX(LINEST('Daily Data'!T$880:T$3934,'Regression Inputs'!$E$881:$E$3935,TRUE(),TRUE()),1,1) -> 2.1845376 | O29: =N29/INDEX(LINEST('Daily Data'!T$880:T$3934,'Regression Inputs'!$E$881:$E$3935,TRUE(),TRUE()),2,1) -> 61.306393 | P29: =TDIST(ABS(O29),INDEX(LINEST('Daily Data'!T$880:T$3934,'Regression Inputs'!$E$881:$E$3935,TRUE(),TRUE()),4,2),2) -> 0 | T29: =INDEX(LINEST('Daily Data'!T$880:T$3934,'Regression Inputs'!$E$881:$E$3935,TRUE(),TRUE()),3,1) -> 0.5517857 | U29: =1-(1-T29)*(D29-1)/(D29-1-1) -> 0.55163888 | V29: =D29*LN(2*PI())+D29*LN(INDEX(LINEST('Daily Data'!T$880:T$3934,'Regression Inputs'!$E$881:$E$3935,TRUE(),TRUE()),5,2)/D29)+D29+2*(1+1) -> -15350.01 | W29: =D29*LN(2*PI())+D29*LN(INDEX(LINEST('Daily Data'!T$880:T$3934,'Regression Inputs'!$E$881:$E$3935,TRUE(),TRUE()),5,2)/D29)+D29+LN(D29)*(1+1) -> -15337.961
A30: GDXJ | B30: IAU+GLD | C30: 2 | D30: =COUNT('Daily Data'!T$880:T$3934) -> 3055 | E30: =INDEX(LINEST('Daily Data'!T$880:T$3934,'Regression Inputs'!$R$881:$S$3935,TRUE(),TRUE()),1,3)*10000 -> -1.6383663 | F30: =INDEX(LINEST('Daily Data'!T$880:T$3934,'Regression Inputs'!$R$881:$S$3935,TRUE(),TRUE()),1,3)/INDEX(LINEST('Daily Data'!T$880:T$3934,'Regression Inputs'!$R$881:$S$3935,TRUE(),TRUE()),2,3) -> -0.46158191 | G30: =TDIST(ABS(F30),INDEX(LINEST('Daily Data'!T$880:T$3934,'Regression Inputs'!$R$881:$S$3935,TRUE(),TRUE()),4,2),2) -> 0.64441406 | K30: =INDEX(LINEST('Daily Data'!T$880:T$3934,'Regression Inputs'!$R$881:$S$3935,TRUE(),TRUE()),1,2) -> -0.50673299 | L30: =K30/INDEX(LINEST('Daily Data'!T$880:T$3934,'Regression Inputs'!$R$881:$S$3935,TRUE(),TRUE()),2,2) -> -0.79444749 | M30: =TDIST(ABS(L30),INDEX(LINEST('Daily Data'!T$880:T$3934,'Regression Inputs'!$R$881:$S$3935,TRUE(),TRUE()),4,2),2) -> 0.42699674 | N30: =INDEX(LINEST('Daily Data'!T$880:T$3934,'Regression Inputs'!$R$881:$S$3935,TRUE(),TRUE()),1,1) -> 2.6909035 | O30: =N30/INDEX(LINEST('Daily Data'!T$880:T$3934,'Regression Inputs'!$R$881:$S$3935,TRUE(),TRUE()),2,1) -> 4.2152288 | P30: =TDIST(ABS(O30),INDEX(LINEST('Daily Data'!T$880:T$3934,'Regression Inputs'!$R$881:$S$3935,TRUE(),TRUE()),4,2),2) -> 2.5676639e-05 | T30: =INDEX(LINEST('Daily Data'!T$880:T$3934,'Regression Inputs'!$R$881:$S$3935,TRUE(),TRUE()),3,1) -> 0.55187837 | U30: =1-(1-T30)*(D30-1)/(D30-2-1) -> 0.55158471 | V30: =D30*LN(2*PI())+D30*LN(INDEX(LINEST('Daily Data'!T$880:T$3934,'Regression Inputs'!$R$881:$S$3935,TRUE(),TRUE()),5,2)/D30)+D30+2*(2+1) -> -15348.642 | W30: =D30*LN(2*PI())+D30*LN(INDEX(LINEST('Daily Data'!T$880:T$3934,'Regression Inputs'!$R$881:$S$3935,TRUE(),TRUE()),5,2)/D30)+D30+LN(D30)*(2+1) -> -15330.568
A31: GDXJ | B31: IAU | C31: 1 | D31: =COUNT('Daily Data'!T$880:T$3934) -> 3055 | E31: =INDEX(LINEST('Daily Data'!T$880:T$3934,'Regression Inputs'!$C$881:$C$3935,TRUE(),TRUE()),1,2)*10000 -> -1.7764027 | F31: =INDEX(LINEST('Daily Data'!T$880:T$3934,'Regression Inputs'!$C$881:$C$3935,TRUE(),TRUE()),1,2)/INDEX(LINEST('Daily Data'!T$880:T$3934,'Regression Inputs'!$C$881:$C$3935,TRUE(),TRUE()),2,2) -> -0.4991238 | G31: =TDIST(ABS(F31),INDEX(LINEST('Daily Data'!T$880:T$3934,'Regression Inputs'!$C$881:$C$3935,TRUE(),TRUE()),4,2),2) -> 0.61772813 | K31: =INDEX(LINEST('Daily Data'!T$880:T$3934,'Regression Inputs'!$C$881:$C$3935,TRUE(),TRUE()),1,1) -> 2.1777301 | L31: =K31/INDEX(LINEST('Daily Data'!T$880:T$3934,'Regression Inputs'!$C$881:$C$3935,TRUE(),TRUE()),2,1) -> 60.995481 | M31: =TDIST(ABS(L31),INDEX(LINEST('Daily Data'!T$880:T$3934,'Regression Inputs'!$C$881:$C$3935,TRUE(),TRUE()),4,2),2) -> 0 | T31: =INDEX(LINEST('Daily Data'!T$880:T$3934,'Regression Inputs'!$C$881:$C$3935,TRUE(),TRUE()),3,1) -> 0.54926949 | U31: =1-(1-T31)*(D31-1)/(D31-1-1) -> 0.54912185 | V31: =D31*LN(2*PI())+D31*LN(INDEX(LINEST('Daily Data'!T$880:T$3934,'Regression Inputs'!$C$881:$C$3935,TRUE(),TRUE()),5,2)/D31)+D31+2*(1+1) -> -15332.908 | W31: =D31*LN(2*PI())+D31*LN(INDEX(LINEST('Daily Data'!T$880:T$3934,'Regression Inputs'!$C$881:$C$3935,TRUE(),TRUE()),5,2)/D31)+D31+LN(D31)*(1+1) -> -15320.859
A32: GDXJ | B32: SPY+TLT | C32: 2 | D32: =COUNT('Daily Data'!T$880:T$3934) -> 3055 | E32: =INDEX(LINEST('Daily Data'!T$880:T$3934,'Regression Inputs'!$O$881:$P$3935,TRUE(),TRUE()),1,3)*10000 -> -5.0493748 | F32: =INDEX(LINEST('Daily Data'!T$880:T$3934,'Regression Inputs'!$O$881:$P$3935,TRUE(),TRUE()),1,3)/INDEX(LINEST('Daily Data'!T$880:T$3934,'Regression Inputs'!$O$881:$P$3935,TRUE(),TRUE()),2,3) -> -0.99359814 | G32: =TDIST(ABS(F32),INDEX(LINEST('Daily Data'!T$880:T$3934,'Regression Inputs'!$O$881:$P$3935,TRUE(),TRUE()),4,2),2) -> 0.32049732 | H32: =INDEX(LINEST('Daily Data'!T$880:T$3934,'Regression Inputs'!$O$881:$P$3935,TRUE(),TRUE()),1,2) -> 0.8965296 | I32: =H32/INDEX(LINEST('Daily Data'!T$880:T$3934,'Regression Inputs'!$O$881:$P$3935,TRUE(),TRUE()),2,2) -> 16.727946 | J32: =TDIST(ABS(I32),INDEX(LINEST('Daily Data'!T$880:T$3934,'Regression Inputs'!$O$881:$P$3935,TRUE(),TRUE()),4,2),2) -> 3.6234132e-60 | Q32: =INDEX(LINEST('Daily Data'!T$880:T$3934,'Regression Inputs'!$O$881:$P$3935,TRUE(),TRUE()),1,1) -> 0.6799209 | R32: =Q32/INDEX(LINEST('Daily Data'!T$880:T$3934,'Regression Inputs'!$O$881:$P$3935,TRUE(),TRUE()),2,1) -> 10.834893 | S32: =TDIST(ABS(R32),INDEX(LINEST('Daily Data'!T$880:T$3934,'Regression Inputs'!$O$881:$P$3935,TRUE(),TRUE()),4,2),2) -> 7.2065617e-27 | T32: =INDEX(LINEST('Daily Data'!T$880:T$3934,'Regression Inputs'!$O$881:$P$3935,TRUE(),TRUE()),3,1) -> 0.087458898 | U32: =1-(1-T32)*(D32-1)/(D32-2-1) -> 0.086860902 | V32: =D32*LN(2*PI())+D32*LN(INDEX(LINEST('Daily Data'!T$880:T$3934,'Regression Inputs'!$O$881:$P$3935,TRUE(),TRUE()),5,2)/D32)+D32+2*(2+1) -> -13176.022 | W32: =D32*LN(2*PI())+D32*LN(INDEX(LINEST('Daily Data'!T$880:T$3934,'Regression Inputs'!$O$881:$P$3935,TRUE(),TRUE()),5,2)/D32)+D32+LN(D32)*(2+1) -> -13157.948
A33: GDXJ | B33: SPY | C33: 1 | D33: =COUNT('Daily Data'!T$880:T$3934) -> 3055 | E33: =INDEX(LINEST('Daily Data'!T$880:T$3934,'Regression Inputs'!$A$881:$A$3935,TRUE(),TRUE()),1,2)*10000 -> -1.5988041 | F33: =INDEX(LINEST('Daily Data'!T$880:T$3934,'Regression Inputs'!$A$881:$A$3935,TRUE(),TRUE()),1,2)/INDEX(LINEST('Daily Data'!T$880:T$3934,'Regression Inputs'!$A$881:$A$3935,TRUE(),TRUE()),2,2) -> -0.30938417 | G33: =TDIST(ABS(F33),INDEX(LINEST('Daily Data'!T$880:T$3934,'Regression Inputs'!$A$881:$A$3935,TRUE(),TRUE()),4,2),2) -> 0.75705042 | H33: =INDEX(LINEST('Daily Data'!T$880:T$3934,'Regression Inputs'!$A$881:$A$3935,TRUE(),TRUE()),1,1) -> 0.63027244 | I33: =H33/INDEX(LINEST('Daily Data'!T$880:T$3934,'Regression Inputs'!$A$881:$A$3935,TRUE(),TRUE()),2,1) -> 12.987727 | J33: =TDIST(ABS(I33),INDEX(LINEST('Daily Data'!T$880:T$3934,'Regression Inputs'!$A$881:$A$3935,TRUE(),TRUE()),4,2),2) -> 1.3962948e-37 | T33: =INDEX(LINEST('Daily Data'!T$880:T$3934,'Regression Inputs'!$A$881:$A$3935,TRUE(),TRUE()),3,1) -> 0.052358087 | U33: =1-(1-T33)*(D33-1)/(D33-1-1) -> 0.05204769 | V33: =D33*LN(2*PI())+D33*LN(INDEX(LINEST('Daily Data'!T$880:T$3934,'Regression Inputs'!$A$881:$A$3935,TRUE(),TRUE()),5,2)/D33)+D33+2*(1+1) -> -13062.715 | W33: =D33*LN(2*PI())+D33*LN(INDEX(LINEST('Daily Data'!T$880:T$3934,'Regression Inputs'!$A$881:$A$3935,TRUE(),TRUE()),5,2)/D33)+D33+LN(D33)*(1+1) -> -13050.666
A34: GDXJ | B34: TLT | C34: 1 | D34: =COUNT('Daily Data'!T$880:T$3934) -> 3055 | E34: =INDEX(LINEST('Daily Data'!T$880:T$3934,'Regression Inputs'!$G$881:$G$3935,TRUE(),TRUE()),1,2)*10000 -> 1.5802254 | F34: =INDEX(LINEST('Daily Data'!T$880:T$3934,'Regression Inputs'!$G$881:$G$3935,TRUE(),TRUE()),1,2)/INDEX(LINEST('Daily Data'!T$880:T$3934,'Regression Inputs'!$G$881:$G$3935,TRUE(),TRUE()),2,2) -> 0.29856524 | G34: =TDIST(ABS(F34),INDEX(LINEST('Daily Data'!T$880:T$3934,'Regression Inputs'!$G$881:$G$3935,TRUE(),TRUE()),4,2),2) -> 0.76529211 | Q34: =INDEX(LINEST('Daily Data'!T$880:T$3934,'Regression Inputs'!$G$881:$G$3935,TRUE(),TRUE()),1,1) -> 0.19860407 | R34: =Q34/INDEX(LINEST('Daily Data'!T$880:T$3934,'Regression Inputs'!$G$881:$G$3935,TRUE(),TRUE()),2,1) -> 3.4090107 | S34: =TDIST(ABS(R34),INDEX(LINEST('Daily Data'!T$880:T$3934,'Regression Inputs'!$G$881:$G$3935,TRUE(),TRUE()),4,2),2) -> 0.00066044364 | T34: =INDEX(LINEST('Daily Data'!T$880:T$3934,'Regression Inputs'!$G$881:$G$3935,TRUE(),TRUE()),3,1) -> 0.003792101 | U34: =1-(1-T34)*(D34-1)/(D34-1-1) -> 0.0034657964 | V34: =D34*LN(2*PI())+D34*LN(INDEX(LINEST('Daily Data'!T$880:T$3934,'Regression Inputs'!$G$881:$G$3935,TRUE(),TRUE()),5,2)/D34)+D34+2*(1+1) -> -12910.029 | W34: =D34*LN(2*PI())+D34*LN(INDEX(LINEST('Daily Data'!T$880:T$3934,'Regression Inputs'!$G$881:$G$3935,TRUE(),TRUE()),5,2)/D34)+D34+LN(D34)*(1+1) -> -12897.98

Sheet Daily Data
A1: All returns and excess returns computed live from Prices/FedFunds via formulas. ExcessReturn = SimpleReturn − (FEDFUNDS/100)/252.
A2: Date | B2: RF_annual | C2: SPY | D2: IAU | E2: GLD | F2: TLT | G2: GDX | H2: GDXJ | I2: Ret_SPY | J2: Ret_IAU | K2: Ret_GLD | L2: Ret_TLT | M2: Ret_GDX | N2: Ret_GDXJ | O2: ExRet_SPY | P2: ExRet_IAU | Q2: ExRet_GLD | R2: ExRet_TLT | S2: ExRet_GDX | T2: ExRet_GDXJ
A3: ='Prices (input)'!A3 -> 38859 | B3: =LOOKUP(A3,'FedFunds (input)'!$A$3:$A$867,'FedFunds (input)'!$B$3:$B$867)/100 -> 0.0494 | C3: ='Prices (input)'!B3 -> 87.154 | D3: ='Prices (input)'!C3 -> 13.07 | E3: ='Prices (input)'!D3 -> 65.3 | F3: ='Prices (input)'!E3 -> 44.417 | G3: ='Prices (input)'!F3 -> 31.586 | H3: ='Prices (input)'!G3 -> 0 | O3: =IF(I3="","",I3-B3/252) | P3: =IF(J3="","",J3-B3/252) | Q3: =IF(K3="","",K3-B3/252) | R3: =IF(L3="","",L3-B3/252) | S3: =IF(M3="","",M3-B3/252) | T3: =IF(N3="","",N3-B3/252)
A4: ='Prices (input)'!A4 -> 38860 | B4: =LOOKUP(A4,'FedFunds (input)'!$A$3:$A$867,'FedFunds (input)'!$B$3:$B$867)/100 -> 0.0494 | C4: ='Prices (input)'!B4 -> 86.775 | D4: ='Prices (input)'!C4 -> 13.28 | E4: ='Prices (input)'!D4 -> 66.38 | F4: ='Prices (input)'!E4 -> 44.407 | G4: ='Prices (input)'!F4 -> 32.214 | H4: ='Prices (input)'!G4 -> 0 | I4: =IF(OR(C4="",C3=""),"",C4/C3-1) -> -0.0043486243 | J4: =IF(OR(D4="",D3=""),"",D4/D3-1) -> 0.01606733 | K4: =IF(OR(E4="",E3=""),"",E4/E3-1) -> 0.016539051 | L4: =IF(OR(F4="",F3=""),"",F4/F3-1) -> -0.00022513902 | M4: =IF(OR(G4="",G3=""),"",G4/G3-1) -> 0.019882226 | N4: =IF(OR(H4="",H3=""),"",H4/H3-1) | O4: =IF(I4="","",I4-B4/252) -> -0.004544656 | P4: =IF(J4="","",J4-B4/252) -> 0.015871298 | Q4: =IF(K4="","",K4-B4/252) -> 0.016343019 | R4: =IF(L4="","",L4-B4/252) -> -0.00042117077 | S4: =IF(M4="","",M4-B4/252) -> 0.019686195 | T4: =IF(N4="","",N4-B4/252)
A5: ='Prices (input)'!A5 -> 38861 | B5: =LOOKUP(A5,'FedFunds (input)'!$A$3:$A$867,'FedFunds (input)'!$B$3:$B$867)/100 -> 0.0494 | C5: ='Prices (input)'!B5 -> 87.015 | D5: ='Prices (input)'!C5 -> 12.95 | E5: ='Prices (input)'!D5 -> 64.06 | F5: ='Prices (input)'!E5 -> 44.434 | G5: ='Prices (input)'!F5 -> 30.992 | H5: ='Prices (input)'!G5 -> 0 | I5: =IF(OR(C5="",C4=""),"",C5/C4-1) -> 0.0027657736 | J5: =IF(OR(D5="",D4=""),"",D5/D4-1) -> -0.024849398 | K5: =IF(OR(E5="",E4=""),"",E5/E4-1) -> -0.034950286 | L5: =IF(OR(F5="",F4=""),"",F5/F4-1) -> 0.00060801225 | M5: =IF(OR(G5="",G4=""),"",G5/G4-1) -> -0.037933818 | N5: =IF(OR(H5="",H4=""),"",H5/H4-1) | O5: =IF(I5="","",I5-B5/252) -> 0.0025697418 | P5: =IF(J5="","",J5-B5/252) -> -0.025045429 | Q5: =IF(K5="","",K5-B5/252) -> -0.035146318 | R5: =IF(L5="","",L5-B5/252) -> 0.0004119805 | S5: =IF(M5="","",M5-B5/252) -> -0.038129849 | T5: =IF(N5="","",N5-B5/252)
A6: ='Prices (input)'!A6 -> 38862 | B6: =LOOKUP(A6,'FedFunds (input)'!$A$3:$A$867,'FedFunds (input)'!$B$3:$B$867)/100 -> 0.0494 | C6: ='Prices (input)'!B6 -> 88.036 | D6: ='Prices (input)'!C6 -> 12.96 | E6: ='Prices (input)'!D6 -> 64.73 | F6: ='Prices (input)'!E6 -> 44.218 | G6: ='Prices (input)'!F6 -> 32.519 | H6: ='Prices (input)'!G6 -> 0 | I6: =IF(OR(C6="",C5=""),"",C6/C5-1) -> 0.011733609 | J6: =IF(OR(D6="",D5=""),"",D6/D5-1) -> 0.00077220077 | K6: =IF(OR(E6="",E5=""),"",E6/E5-1) -> 0.010458945 | L6: =IF(OR(F6="",F5=""),"",F6/F5-1) -> -0.0048611424 | M6: =IF(OR(G6="",G5=""),"",G6/G5-1) -> 0.04927078 | N6: =IF(OR(H6="",H5=""),"",H6/H5-1) | O6: =IF(I6="","",I6-B6/252) -> 0.011537577 | P6: =IF(J6="","",J6-B6/252) -> 0.00057616903 | Q6: =IF(K6="","",K6-B6/252) -> 0.010262913 | R6: =IF(L6="","",L6-B6/252) -> -0.0050571741 | S6: =IF(M6="","",M6-B6/252) -> 0.049074748 | T6: =IF(N6="","",N6-B6/252)
A7: ='Prices (input)'!A7 -> 38863 | B7: =LOOKUP(A7,'FedFunds (input)'!$A$3:$A$867,'FedFunds (input)'!$B$3:$B$867)/100 -> 0.0494 | C7: ='Prices (input)'!B7 -> 88.457 | D7: ='Prices (input)'!C7 -> 13 | E7: ='Prices (input)'!D7 -> 65.09 | F7: ='Prices (input)'!E7 -> 44.265 | G7: ='Prices (input)'!F7 -> 32.715 | H7: ='Prices (input)'!G7 -> 0 | I7: =IF(OR(C7="",C6=""),"",C7/C6-1) -> 0.0047821346 | J7: =IF(OR(D7="",D6=""),"",D7/D6-1) -> 0.0030864198 | K7: =IF(OR(E7="",E6=""),"",E7/E6-1) -> 0.0055615634 | L7: =IF(OR(F7="",F6=""),"",F7/F6-1) -> 0.0010629156 | M7: =IF(OR(G7="",G6=""),"",G7/G6-1) -> 0.0060272456 | N7: =IF(OR(H7="",H6=""),"",H7/H6-1) | O7: =IF(I7="","",I7-B7/252) -> 0.0045861028 | P7: =IF(J7="","",J7-B7/252) -> 0.002890388 | Q7: =IF(K7="","",K7-B7/252) -> 0.0053655317 | R7: =IF(L7="","",L7-B7/252) -> 0.00086688381 | S7: =IF(M7="","",M7-B7/252) -> 0.0058312139 | T7: =IF(N7="","",N7-B7/252)
A8: ='Prices (input)'!A8 -> 38867 | B8: =LOOKUP(A8,'FedFunds (input)'!$A$3:$A$867,'FedFunds (input)'!$B$3:$B$867)/100 -> 0.0494 | C8: ='Prices (input)'!B8 -> 87.064 | D8: ='Prices (input)'!C8 -> 13.06 | E8: ='Prices (input)'!D8 -> 65.2 | F8: ='Prices (input)'!E8 -> 44.187 | G8: ='Prices (input)'!F8 -> 32.341 | H8: ='Prices (input)'!G8 -> 0 | I8: =IF(OR(C8="",C7=""),"",C8/C7-1) -> -0.015747764 | J8: =IF(OR(D8="",D7=""),"",D8/D7-1) -> 0.0046153846 | K8: =IF(OR(E8="",E7=""),"",E8/E7-1) -> 0.0016899677 | L8: =IF(OR(F8="",F7=""),"",F8/F7-1) -> -0.0017621145 | M8: =IF(OR(G8="",G7=""),"",G8/G7-1) -> -0.011432065 | N8: =IF(OR(H8="",H7=""),"",H8/H7-1) | O8: =IF(I8="","",I8-B8/252) -> -0.015943796 | P8: =IF(J8="","",J8-B8/252) -> 0.0044193529 | Q8: =IF(K8="","",K8-B8/252) -> 0.001493936 | R8: =IF(L8="","",L8-B8/252) -> -0.0019581463 | S8: =IF(M8="","",M8-B8/252) -> -0.011628097 | T8: =IF(N8="","",N8-B8/252)
